Traceback (most recent call last):
  File "/Users/kvarada/miniforge3/envs/jbook/lib/python3.12/site-packages/jupyter_cache/executors/utils.py", line 58, in single_nb_execution
    executenb(
  File "/Users/kvarada/miniforge3/envs/jbook/lib/python3.12/site-packages/nbclient/client.py", line 1314, in execute
    return NotebookClient(nb=nb, resources=resources, km=km, **kwargs).execute()
           ^^^^^^^^^^^^^^^^^^^^^^^^^^^^^^^^^^^^^^^^^^^^^^^^^^^^^^^^^^^^^^^^^^^^^
  File "/Users/kvarada/miniforge3/envs/jbook/lib/python3.12/site-packages/jupyter_core/utils/__init__.py", line 165, in wrapped
    return loop.run_until_complete(inner)
           ^^^^^^^^^^^^^^^^^^^^^^^^^^^^^^
  File "/Users/kvarada/miniforge3/envs/jbook/lib/python3.12/asyncio/base_events.py", line 687, in run_until_complete
    return future.result()
           ^^^^^^^^^^^^^^^
  File "/Users/kvarada/miniforge3/envs/jbook/lib/python3.12/site-packages/nbclient/client.py", line 709, in async_execute
    await self.async_execute_cell(
  File "/Users/kvarada/miniforge3/envs/jbook/lib/python3.12/site-packages/nbclient/client.py", line 1062, in async_execute_cell
    await self._check_raise_for_error(cell, cell_index, exec_reply)
  File "/Users/kvarada/miniforge3/envs/jbook/lib/python3.12/site-packages/nbclient/client.py", line 918, in _check_raise_for_error
    raise CellExecutionError.from_cell_and_msg(cell, exec_reply_content)
nbclient.exceptions.CellExecutionError: An error occurred while executing the following cell:
------------------
import img_classify
from PIL import Image
import glob
import matplotlib.pyplot as plt
# Predict topn labels and their associated probabilities for unseen images
images = glob.glob(DATA_DIR + "test_images/*.*")
class_labels_file = DATA_DIR + 'imagenet_classes.txt'
for img_path in images:
    img = Image.open(img_path).convert('RGB')
    img.load()
    plt.imshow(img)
    plt.show();    
    df = img_classify.classify_image(img_path, class_labels_file)
    print(df.to_string(index=False))
    print("--------------------------------------------------------------")
------------------


[0;31m---------------------------------------------------------------------------[0m
[0;31mModuleNotFoundError[0m                       Traceback (most recent call last)
Cell [0;32mIn[10], line 1[0m
[0;32m----> 1[0m [38;5;28;01mimport[39;00m [38;5;21;01mimg_classify[39;00m
[1;32m      2[0m [38;5;28;01mfrom[39;00m [38;5;21;01mPIL[39;00m [38;5;28;01mimport[39;00m Image
[1;32m      3[0m [38;5;28;01mimport[39;00m [38;5;21;01mglob[39;00m

[0;31mModuleNotFoundError[0m: No module named 'img_classify'

